<!DOCTYPE html>
<html lang="en">

<head>
    <meta charset="UTF-8">
    <meta http-equiv="X-UA-Compatible" content="IE=edge">
    <meta name="viewport" content="width=device-width, initial-scale=1.0">
    <title>Document</title>
</head>

<body>

    <script>
        // 为了避免在Promise中出现回调地狱的情况，Promise有链式调用的操作
        // 1.Promise对象的then方法会返回一个全新的Promise对象
        // 2.后面的then方法就是在为上一个then返回的Promise注册一个回调函数
        // 3.前面的then方法中回调函数的返回值会作为后面then方法回调的参数
        // 4.如果回调中返回的是Promise，那后面的then方法的回调会等待它的结束
        const promise = new Promise(function (resolve, reject) {
            resolve(200);
            // reject(404);
        });
        promise.then((result) => {
            console.log('成功了1', result);
            return 我会被catch捕获到; // return 会将return之后的值继续传递下去，这里因为‘我会被catch捕获到’没有加引号，因此是变量，又因为没有定义该变量，固然这是个错误会被catch捕获到
        }).catch((err) => { // catch相当于是then(undefined, function xxx(xxx) {})
            console.log('失败了1', err);
        }); // 由于Promise链上，任何一个异常都会一直传递下去直至被捕获，所以.catch方法像是给整个Promise链注册了失败回调函数

        promise.then(function (result) {
            console.log('成功了2', result);
            return 我不会被catch捕获到;
        }, function (err) {
            console.log('失败了2', err);
        });

        // 比较上面两者之间的区别，如果使用.catch方法可以捕获到前面的Promise的错误，而使用在then里指定失败回调函数则不会捕获到同级的then返回的Promise中的错误
        // 例如在第二个例子中，function (err) {} 捕获不到当前then返回的Promise的错误，这个错误会被传递到下一级再被捕获（如果下一级有失败回调函数），这样就会出现bug
        // 而.then和.catch搭配使用可以精确捕获Promise链上传递的错误
    </script>
</body>

</html>